Workbook

Sheet Sheet1
A1: Date | B1: Project | C1: Models | D1: Description | E1: Faction | F1: Brand | H1: Total Painted | J1: Project List
A2: 43405 | B2: Practice | C2: 8 | D2: Grots | E2: Chaos | F2: GW | H2: =SUM(C2:C1032) -> 553 | J2: Practice
A3: 43770 | B3: Practice | C3: 10 | D3: Brimstone, Blue and Pink Horrors | E3: Chaos | F3: GW | J3: Khorne Army
A4: 43435 | B4: Practice | C4: 8 | D4: Kairic Acolytes | E4: Chaos | F4: GW | H4: Current Project | J4: Slaves Army
A5: 43466 | B5: Practice | C5: 6 | D5: Tzaangors | E5: Chaos | F5: GW | H5: Belthanos | J5: Ulthwé Army
A6: 43466 | B6: 35mm Models | C6: 1 | D6: Assassin | E6: Dark Elves | F6: GW | J6: Harlequins Army
A7: 43466 | B7: Practice | C7: 6 | D7: Chaos Familliars | E7: Chaos | F7: GW | H7: Most Used Paints | J7: Lumineth Army
A8: 43497 | B8: Khorne Army | C8: 6 | D8: Bloodletters | E8: Khorne Bloodbound | F8: GW | H8: =INDEX(Paints!A:A, MATCH(LARGE(Paints!D:D, 1), Paints!D:D, 0)) -> Dark Turquoise | J8: High Elves Army
A9: 43497 | B9: High Elves Army | C9: 5 | D9: Lothern Seaguard | E9: High Elves | F9: GW | H9: {=IFERROR(INDEX(Paints!A:A, SMALL(IF(Paints!D:D=LARGE(Paints!D:D, 2), ROW(Paints!D:D), ""), 2)), INDEX(Paints!A:A, MATCH(LARGE(Paints!D:D, 3), Paints!D:D, 0)))} -> Anthracite Grey | J9: 35mm Models
A10: 43525 | B10: Khorne Army | C10: 40 | D10: Bloodreavers | E10: Khorne Bloodbound | F10: GW | H10: {=IFERROR(INDEX(Paints!A:A, SMALL(IF(Paints!D:D=LARGE(Paints!D:D, 3), ROW(Paints!D:D), ""), 3)), INDEX(Paints!A:A, MATCH(LARGE(Paints!D:D, 4), Paints!D:D, 0)))} -> Dragon Blood | J10: Tunguska Warband
A11: 43556 | B11: Khorne Army | C11: 15 | D11: Bloodwarriors | E11: Khorne Bloodbound | F11: GW | H11: {=IFERROR(INDEX(Paints!A:A, SMALL(IF(Paints!D:D=LARGE(Paints!D:D, 4), ROW(Paints!D:D), ""), 4)), INDEX(Paints!A:A, MATCH(LARGE(Paints!D:D, 5), Paints!D:D, 0)))} -> Grimy Grey | J11: Sylvaneth Army
A12: 43586 | B12: Khorne Army | C12: 5 | D12: Wrathmongers | E12: Khorne Bloodbound | F12: GW | H12: {=IFERROR(INDEX(Paints!A:A, SMALL(IF(Paints!D:D=LARGE(Paints!D:D, 5), ROW(Paints!D:D), ""), 5)), INDEX(Paints!A:A, MATCH(LARGE(Paints!D:D, 6), Paints!D:D, 0)))} -> Japanese Brown
A13: 43586 | B13: Khorne Army | C13: 1 | D13: Bloodstoker | E13: Khorne Bloodbound | F13: GW
A14: 43586 | B14: Khorne Army | C14: 1 | D14: Slaughter Priest | E14: Khorne Bloodbound | F14: GW
A15: 43586 | B15: Khorne Army | C15: 10 | D15: Flesh Hounds | E15: Khorne Bloodbound | F15: GW
A16: 43617 | B16: Khorne Army | C16: 1 | D16: Bloodsecrator | E16: Khorne Bloodbound | F16: GW
A17: 43617 | B17: Khorne Army | C17: 1 | D17: Karanak | E17: Khorne Bloodbound | F17: GW
A18: 43617 | B18: Khorne Army | C18: 1 | D18: Migthy Lord of Khorne | E18: Khorne Bloodbound | F18: GW | H18: My Must-Have Paints
A19: 43617 | B19: Khorne Army | C19: 3 | D19: Skullcrushers | E19: Khorne Bloodbound | F19: GW | H19: Bright Ivory
A20: 43647 | B20: Khorne Army | C20: 1 | D20: Khorgorath | E20: Khorne Bloodbound | F20: GW | H20: Light Flesh
A21: 43647 | B21: Ulthwé Army | C21: 22 | D21: Black Guardians | E21: Aldeari | F21: GW | H21: Laser Yellow
A22: 43678 | B22: Khorne Army | C22: 1 | D22: Khorgorath | E22: Khorne Bloodbound | F22: GW | H22: Bismuth Yellow
A23: 43678 | B23: Khorne Army | C23: 4 | D23: Judgements of Khorne | E23: Khorne Bloodbound | F23: GW | H23: Tenebrous Grey
A24: 43678 | B24: Khorne Army | C24: 1 | D24: Slaughter Priest | E24: Khorne Bloodbound | F24: GW
A25: 43678 | B25: Ulthwé Army | C25: 6 | D25: Windriders | E25: Aldeari | F25: GW
A26: 43709 | B26: Khorne Army | C26: 1 | D26: Slaughter Priest | E26: Khorne Bloodbound | F26: GW
A27: 43709 | B27: Khorne Army | C27: 1 | D27: Skullgrinder | E27: Khorne Bloodbound | F27: GW
A28: 43709 | B28: Khorne Army | C28: 1 | D28: Exalted Deathbringer | E28: Khorne Bloodbound | F28: GW
A29: 43739 | B29: Ulthwé Army | C29: 2 | D29: Wave Serpents | E29: Aldeari | F29: GW
A30: 43739 | B30: Ulthwé Army | C30: 10 | D30: Rangers | E30: Aldeari | F30: GW
A31: 43739 | B31: Ulthwé Army | C31: 6 | D31: Fire Dragons | E31: Aldeari | F31: GW
A32: 43739 | B32: Ulthwé Army | C32: 6 | D32: Howling Banshees | E32: Aldeari | F32: GW
A33: 43739 | B33: Ulthwé Army | C33: 7 | D33: Warlock Conclave | E33: Aldeari | F33: GW
A34: 43739 | B34: Ulthwé Army | C34: 2 | D34: Fire Prisms | E34: Aldeari | F34: GW
A35: 43739 | B35: 35mm Models | C35: 1 | D35: Aquiles | E35: Aleph | F35: Corvus Belli
... A82: 43983 | B82: Slaves Army | C82: 5 | D82: Chaos Warriors | E82: Slaves to Darkness | F82: GW
A83: 44013 | C83: 0
A84: 44044 | B84: Practice | C84: 1 | D84: Katakros Mortach of the Necropolis | E84: Ossiarch Boneripers | F84: GW
A85: 44044 | B85: Practice | C85: 2 | D85: Ephrael Stern and Kyganil | E85: Adepta Sororitas | F85: GW
A86: 44044 | B86: Practice | C86: 3 | D86: Marneus Calgar | E86: Ultramarines | F86: GW
...

Sheet Paints
A1: Paint | B1: Brand | C1: Series | D1: Total Used | E1: Ulthwé | F1: Details U | G1: Ynnari | H1: Details Y | I1: Harlequins | J1: Details H | K1: Sylvaneth | L1: Details S | M1: Lumineth | N1: Details L | O1: High Elves | P1: Details H2
A2: Afro Shadow | B2: AK | C2: Color Punch | D2: =SUM(E2,G2,I2,K2,M2,O2) -> 3 | E2: 1 | F2: NMM Shadow | G2: 1 | H2: NMM Gold | K2: 1 | L2: Whole Wood
A3: Anthracite Grey | B3: AK | C3: 3rd Gen | D3: =SUM(E3,G3,I3,K3,M3,O3) -> 3 | K3: 1 | L3: Dragonfly | M3: 1 | N3: Up NMM | O3: 1 | P3: Gems
A4: Aquatic Turquoise | B4: AK | C4: 3rd Gen | D4: =SUM(E4,G4,I4,K4,M4,O4) -> 2 | G4: 1 | H4: Gems | K4: 1 | L4: Leaves
A5: Black Red | B5: AK | C5: 3rd Gen | D5: =SUM(E5,G5,I5,K5,M5,O5) -> 2 | K5: 1 | L5: Green NMM | O5: 1 | P5: Lizard Whole
A6: British Khaki | B6: AK | C6: 3rd Gen | D6: =SUM(E6,G6,I6,K6,M6,O6) -> 2 | E6: 1 | F6: Gold | G6: 1 | H6: NMM Gold
A7: Deep Purple | B7: AK | C7: 3rd Gen | D7: =SUM(E7,G7,I7,K7,M7,O7) -> 0
A8: Deep Violet | B8: AK | C8: 3rd Gen | D8: =SUM(E8,G8,I8,K8,M8,O8) -> 0
A9: Dragon Blood | B9: AK | C9: Color Punch | D9: =SUM(E9,G9,I9,K9,M9,O9) -> 3 | E9: 1 | F9: Reds | G9: 1 | H9: Armour | K9: 1 | L9: Leaves
A10: French Blue | B10: AK | C10: 3rd Gen | D10: =SUM(E10,G10,I10,K10,M10,O10) -> 1 | G10: 1 | H10: NMM Silver
A11: Golden Olive | B11: AK | C11: 3rd Gen | D11: =SUM(E11,G11,I11,K11,M11,O11) -> 1 | K11: 1 | L11: Green NMM
A12: Golden Yellow | B12: AK | C12: 3rd Gen | D12: =SUM(E12,G12,I12,K12,M12,O12) -> 1 | O12: 1 | P12: Gold NMM
A13: Graphite | B13: AK | C13: 3rd Gen | D13: =SUM(E13,G13,I13,K13,M13,O13) -> 1 | E13: 1 | F13: Up clothes
A14: Grimy Grey | B14: AK | C14: 3rd Gen | D14: =SUM(E14,G14,I14,K14,M14,O14) -> 3 | E14: 1 | F14: Bone | I14: 1 | J14: Bone | K14: 1 | L14: Wood
A15: Hull Red | B15: AK | C15: 3rd Gen | D15: =SUM(E15,G15,I15,K15,M15,O15) -> 0
A16: Japanese Brown | B16: AK | C16: 3rd Gen | D16: =SUM(E16,G16,I16,K16,M16,O16) -> 3 | E16: 1 | F16: Gold | G16: 1 | H16: NMM Gold | O16: 1 | P16: Gold NMM
A17: Laser Yellow | B17: AK | C17: 3rd Gen | D17: =SUM(E17,G17,I17,K17,M17,O17) -> 0 | E17: 0 | F17: Must | G17: 0 | H17: Must | I17: 0 | J17: Must | K17: 0 | L17: Must | M17: 0 | N17: Must | O17: 0 | P17: Must
A18: Light Flesh | B18: AK | C18: 3rd Gen | D18: =SUM(E18,G18,I18,K18,M18,O18) -> 0 | E18: 0 | F18: Must | G18: 0 | H18: Must | I18: 0 | J18: Must | K18: 0 | L18: Must | M18: 0 | N18: Must | O18: 0 | P18: Must
A19: Lilac | B19: AK | C19: 3rd Gen | D19: =SUM(E19,G19,I19,K19,M19,O19) -> 2 | K19: 1 | L19: Dragonfly | M19: 1 | N19: Up NMM
A20: Luminous Flesh | B20: AK | C20: 3rd Gen | D20: =SUM(E20,G20,I20,K20,M20,O20) -> 2 | M20: 1 | N20: Skin | O20: 1 | P20: Skin
A21: Luminous Green | B21: AK | C21: 3rd Gen | D21: =SUM(E21,G21,I21,K21,M21,O21) -> 0
A22: Luminous Orange | B22: AK | C22: 3rd Gen | D22: =SUM(E22,G22,I22,K22,M22,O22) -> 1 | K22: 1 | L22: Energy
A23: Pistachio | B23: AK | C23: 3rd Gen | D23: =SUM(E23,G23,I23,K23,M23,O23) -> 0
A24: Purple | B24: AK | C24: 3rd Gen | D24: =SUM(E24,G24,I24,K24,M24,O24) -> 0
A25: Purulent Yellow | B25: AK | C25: 3rd Gen | D25: =SUM(E25,G25,I25,K25,M25,O25) -> 0
A26: Reddish Grey | B26: AK | C26: 3rd Gen | D26: =SUM(E26,G26,I26,K26,M26,O26) -> 2 | M26: 1 | N26: Clothes | O26: 1 | P26: Clothes
A27: Sahara Yellow | B27: AK | C27: 3rd Gen | D27: =SUM(E27,G27,I27,K27,M27,O27) -> 1 | O27: 1 | P27: Gold NMM
A28: Sand Yellow | B28: AK | C28: 3rd Gen | D28: =SUM(E28,G28,I28,K28,M28,O28) -> 1 | M28: 1 | N28: Up NMM
A29: Silver Grey | B29: AK | C29: 3rd Gen | D29: =SUM(E29,G29,I29,K29,M29,O29) -> 2 | E29: 1 | F29: Up Tenebrous | K29: 1 | L29: White NMMM
A30: Tenebrous Grey | B30: AK | C30: 3rd Gen | D30: =SUM(E30,G30,I30,K30,M30,O30) -> 0 | E30: 0 | F30: Must | G30: 0 | H30: Must | I30: 0 | J30: Must | K30: 0 | L30: Must | M30: 0 | N30: Must | O30: 0 | P30: Must
A31: Violed Red | B31: AK | C31: 3rd Gen | D31: =SUM(E31,G31,I31,K31,M31,O31) -> 2 | G31: 1 | H31: Up Dragon Blood | K31: 1 | L31: Skin
A32: Volcanic Yellow | B32: AK | C32: 3rd Gen | D32: =SUM(E32,G32,I32,K32,M32,O32) -> 1 | K32: 1 | L32: Energy
A33: Wine Red | B33: AK | C33: 3rd Gen | D33: =SUM(E33,G33,I33,K33,M33,O33) -> 3 | E33: 1 | F33: Reds | K33: 1 | L33: Leaves (up Yellow) | M33: 1 | N33: Reds
A34: Basilisk Red | B34: Army Painter | C34: Warpaints | D34: =SUM(E34,G34,I34,K34,M34,O34) -> 3 | E34: 1 | F34: Reds | G34: 1 | H34: Reds | K34: 1 | L34: Details
A35: Blood Chalice | B35: Army Painter | C35: Warpaints | D35: =SUM(E35,G35,I35,K35,M35,O35) -> 0
A36: Carnelian Skin | B36: Army Painter | C36: Warpaints | D36: =SUM(E36,G36,I36,K36,M36,O36) -> 0
A37: Doomfire Drab | B37: Army Painter | C37: Warpaints | D37: =SUM(E37,G37,I37,K37,M37,O37) -> 1 | K37: 1 | L37: Lights
A38: Dragon Red | B38: Army Painter | C38: Warpaints | D38: =SUM(E38,G38,I38,K38,M38,O38) -> 0
A39: Elder Flower | B39: Army Painter | C39: Warpaints | D39: =SUM(E39,G39,I39,K39,M39,O39) -> 0
A40: Figgy Pink | B40: Army Painter | C40: Warpaints | D40: =SUM(E40,G40,I40,K40,M40,O40) -> 0
...
